Workbook

Sheet Al
K1: Reference
C2: 1 kWh= | D2: 3.6 | E2: MJ
C3: China | D3: 582 | E3: gCO2/kWh | I3: =D3/1000/$D$2 -> 0.16166667 | J3: kgCO2 eq/MJ | K3: kgCO2 eq/MJ
C4: Taiwan | D4: 642 | E4: gCO2/kWh | I4: =D4/1000/$D$2 -> 0.17833333 | J4: kgCO2 eq/MJ | K4: https://ourworldindata.org/grapher/carbon-intensity-electricity
C5: Japan | D5: 485 | E5: gCO2/kWh | I5: =D5/1000/$D$2 -> 0.13472222 | J5: kgCO2 eq/MJ | K5: https://ourworldindata.org/grapher/carbon-intensity-electricity
C6: Germany | D6: 381 | E6: gCO2/kWh | I6: =D6/1000/$D$2 -> 0.10583333 | J6: kgCO2 eq/MJ | K6: https://ourworldindata.org/grapher/carbon-intensity-electricity
C7: Netherlands | D7: 268 | E7: gCO2/kWh | I7: =D7/1000/$D$2 -> 0.074444444 | J7: kgCO2 eq/MJ | K7: https://ourworldindata.org/grapher/carbon-intensity-electricity
D8: heavy load. truck. no trailer. containers | E8: road | F8: 1.8 | G8: MJ/t/km | H8: 0.1669 | I8: kg CO2/km/t | J8: https://cedelft.eu/wp-content/uploads/sites/2/2021/03/CE_Delft_190325_STREAM_Freight_Transport_2020_FINAL.pdf?utm_source=chatgpt.com
B9: wastage of 10% is assumed | D9: 0-999 TEU. heavy load. containers | E9: ship | F9: 0.36 | G9: MJ/t/km | H9: 0.034 | I9: kg CO2/km/t | J9: https://cedelft.eu/wp-content/uploads/sites/2/2021/03/CE_Delft_190325_STREAM_Freight_Transport_2020_FINAL.pdf?utm_source=chatgpt.com
D10: long. heavy load. electric. containers | E10: rail | F10: 0.08 | G10: MJ/t/km | H10: 0.0108 | I10: kg CO2/km/t | J10: https://cedelft.eu/wp-content/uploads/sites/2/2021/03/CE_Delft_190325_STREAM_Freight_Transport_2020_FINAL.pdf?utm_source=chatgpt.com
B11: Aluminium
B12: Weight | D12: Energy | E12: Unit of E | F12: MJ/kg | G12: MJ per bike ( *2.6) | H12: country | I12: kg CO2 eq per bike | J12: Unit of CO2 | K12: Country | L12: Ref
A13: Raw Material extruction: | B13: 2.6 kg | C13: primary al Ingot | D13: 157207 | E13: MJ/t | F13: 157.207 MJ/kg | G13: =157.207*2.6 -> 408.7382 | H13: China | I13: =408.7382*0.16 -> 65.398112 | J13: kg CO2 eq / bike | K13: China | L13: Life Cycle Energy Consumption and Greenhouse Gas Emissions Analysis of Primary and Recycled Aluminum in China
B14: ? | C14: Secondary al ingots | D14: 11730 | E14: MJ/t | F14: 11.73 MJ/kg | H14: China | J14: kg CO2 eq / bike | K14: China
A15: Transportation: | B15: 2.6 kg | C15: Ship transport (1927.3 km) china to taiwan | D15: 0.36 | E15: MJ/t/km | F15: 0.00036 MJ/kg/km | G15: =0.36/1000*2.6*1927.3 -> 1.8039528 | H15: transportation | I15: =2.6*1927.3*H9/1000 -> 0.17037332 | J15: kg CO2 eq / bike
A16: Transportation: | B16: 2.6 kg | C16: Road transport (327 km) (china plant to china harbour) | D16: 1.8 | E16: MJ/t/km | F16: 0.0018 MJ/kg/km | G16: =0.0018*2.6*327 -> 1.53036 | H16: transportation | I16: =2.6*327*H8/1000 -> 0.14189838 | J16: kg CO2 eq / bike
A17: Production: | B17: 2.6 kg | C17: Extrusion | D17: 7.63 | E17: MJ/kg | F17: 7.63 MJ/kg | G17: =7.63*2.6 -> 19.838 | H17: Taiwan | I17: =19.838*0.18 -> 3.57084 | J17: kg CO2 eq / bike | K17: Aluminium extrusion
A18: Production: | B18: 2.6 kg | C18: Hydroforming | D18: 75.6 | E18: MJ/kg | F18: 75.6 MJ/kg | G18: =75.6*2.6 -> 196.56 | H18: Taiwan | I18: =196.56*0.18 -> 35.3808 | J18: kg CO2 eq / bike | K18: Hydroforming paper
A19: Production: | C19: Miter cut tubes 16 cuts | D19: 178.5 | E19: kJ/cut | F19: 0.1785 MJ/cut | G19: =0.1785*16 -> 2.856 | H19: Taiwan | I19: =2.856*0.18 -> 0.51408 | J19: kg CO2 eq / bike | K19: Miter Cut
A20: Production: | C20: Tig weld (tot length=1.7 m) | D20: 38.3 | E20: MJ/m | F20: 38.3 MJ/m | G20: =38.3*1.7 -> 65.11 | H20: Taiwan | I20: =65.11*0.18 -> 11.7198 | J20: kg CO2 eq / bike | K20: TIG welding paper . 38.3 MJ 2.44 kg CO2 for 1 meter TIG welding ref: Life Cycle Assessment (LCA) Results of MIG and TIG Welding Technologies Using the IMPACT 2002+ Methodology
A21: Production: | B21: Heat Treating Aluminum Alloys | C21: Q=m*c*dT | F21: Heat per bike [MJ] | G21: Electricity per bike [MJ] | I21: kg CO2 eq per bike | K21: Reynolds Metals Company . The Company. 1946 - Aluminum alloys - 144 pages
A22: Production: | B22: 896 | C22: Solution heat treatment T=520 °C | F22: =$B$25*$B$22*(520-20)/1000/1000 -> 1.0528 | G22: =F22/0.7 -> 1.504 | H22: Taiwan | I22: =G22*I$4 -> 0.26821333 | K22: '
B23: C=896 J/kg-°C MatWeb: Online Materials Information Resource | C23: Aging 10 h at T=160 °C | F23: =$B$25*$B$22*(160-20)/1000000 -> 0.294784 | G23: =F23/0.7 -> 0.42112 | H23: Taiwan | I23: =G23*I$4 -> 0.075099733 | K23: electrical.thermal efficiency of furnaces=70% "Design and construction of an electric heat treatment furnace using locally sourced materials
E24: total | G24: =G22+G23 -> 1.92512 | I24: =I22+I23 -> 0.34331307
A25: Production: | B25: 2.35 | C25: Painting | D25: 12.51 | E25: MJ/bike | F25: 12.51 MJ/bike | G25: 12.51 | H25: Taiwan | I25: =12.51*0.18 -> 2.2518 | J25: kg CO2 eq / bike
A26: Transportation: | C26: ship transport (18389.5 km) taiwan to rotterdam | D26: 0.36 | E26: MJ/t/km | F26: 0.00036 MJ/kg/km | G26: =0.36/1000*2.35*18389.5 -> 15.557517 | H26: transportation | I26: =2.35*18389.5*H9/1000 -> 1.4693211 | J26: kg CO2 eq / bike
A27: Use phase: | C27: use phase | H27: Netherlands
A28: EoL: | C28: shredding ( 10 cut/bike) | D28: 0.04 | E28: MJ/cut | F28: =0.04 -> 0.04 | G28: 0.4 | H28: Netherlands | I28: =0.4*0.07 -> 0.028 | J28: kg CO2 eq / bike
A29: EoL: | C29: recycling in netherlands | D29: 34 | E29: MJ/kg | F29: 34 MJ/kg | G29: 88.4 | H29: Netherlands | I29: =88.4*0.07 -> 6.188 | J29: kg CO2 eq / bike
A32: Total: | C32: TOTAL | G32: =G13+G15+G16+G17+G18+G19+G20+G22+G23+G25+G26+G28+G29 -> 815.22915 | H32: MJ/Bike frame | I32: =I13+I15+I16+I17+I18+I19+I20+I24+I25+I26+I28+I29 -> 127.17634 | J32: kg CO2 eq / bike
C35: 95 % recycling rate
C38: material recovered (95% recycling rate) | D38: =2.35*0.95 -> 2.2325
C39: material extraction energy per kg AL | D39: =D13/1000 -> 157.207
C40: energy recovered per bike frame | D40: =D39*D38 -> 350.96463
C41: Kg Co2 eg displaced per bike frame (Netherlands) | D41: =350.96*0.07 -> 24.5672
C43: Total energy required for manf per bike | D43: =G32 -> 815.22915
C44: energy recovered per bike frame | D44: =D40 -> 350.96463 | E44: MJ/bike frame
C45: Total kg of CO2 eq per bike frame | D45: =I32 -> 127.17634
C46: Kg Co2 eg displaced per bike frame (Netherlands) | D46: =350.96*0.07 -> 24.5672 | E46: kg CO2 eq / bike
C48: Net energy for producing one bike frame | D48: =D43-D44 -> 464.26452 | E48: MJ/bike frame
...

Sheet CF
D1: Transportation: | J1: Reference:
E2: 1 kWh= | F2: 3.6 | G2: MJ
E3: China | F3: 582 | G3: gCO2/kWh | H3: =F3/1000/$F$2 -> 0.16166667 | I3: kgCO2 eq./MJ | J3: https://ourworldindata.org/grapher/carbon-intensity-electricity
E4: Taiwan | F4: 642 | G4: gCO2/kWh | H4: =F4/1000/$F$2 -> 0.17833333 | I4: kgCO2 eq./MJ | J4: https://ourworldindata.org/grapher/carbon-intensity-electricity
E5: Japan | F5: 485 | G5: gCO2/kWh | H5: =F5/1000/$F$2 -> 0.13472222 | I5: kgCO2 eq./MJ | J5: https://ourworldindata.org/grapher/carbon-intensity-electricity
E6: Germany | F6: 381 | G6: gCO2/kWh | H6: =F6/1000/$F$2 -> 0.10583333 | I6: kgCO2 eq./MJ | J6: https://ourworldindata.org/grapher/carbon-intensity-electricity
E7: Netherlands | F7: 268 | G7: gCO2/kWh | H7: =F7/1000/$F$2 -> 0.074444444 | I7: kgCO2 eq./MJ | J7: https://ourworldindata.org/grapher/carbon-intensity-electricity
D9: wastage of 10% is assumed
D11: Aluminium:
D12: Weight | F12: Energy | H12: kg CO2 eq
D13: 2.6 kg | E13: primary al Ingot | F13: 157207 | G13: MJ/t | H13: 15947 | I13: kg CO2 eq / t
E14: Secondary al ingots
D15: 2.6 kg | E15: Ship transport. 13,000 km | F15: 0.076 | G15: MJ/t/km | H15: 20 | I15: CO2 eq/km/t | J15: https://cedelft.eu/wp-content/uploads/sites/2/2021/03/CE_Delft_190325_STREAM_Freight_Transport_2020_FINAL.pdf?utm_source=chatgpt.com
D16: 2.6 kg | E16: Rail transport. 630 km | F16: 0.129 | G16: MJ/t/km | H16: 12.8 | I16: CO2 eq/km/t | J16: EcoTransit database
D17: 2.6 kg | E17: Extrusion | F17: 7.63 | G17: MJ/kg | H17: 6.57 | I17: CO2 eq/kg | J17: Aluminium extrusion
D18: 2.6 kg | E18: Hydroforming | F18: 75.6 | G18: MJ/kg | H18: ? | J18: Hydroforming paper
E19: Miter cut tubes 16 cuts | F19: 178.5 | G19: kJ/cut | H19: 0.0426 | I19: kg CO2/cut | J19: Miter Cut
E20: Tig weld (tot length=1.7 m) | F20: 38.3 | G20: MJ/m | H20: 2.44 | I20: kg CO2/m | J20: TIG welding paper . 38.3 MJ 2.44 kg CO2 for 1 meter TIG welding ref: Life Cycle Assessment (LCA) Results of MIG and TIG Welding Technologies Using the IMPACT 2002+ Methodology
D21: Heat Treating Aluminum Alloys | E21: Solution heat treatment T=520 °C | J21: Reynolds Metals Company . The Company, 1946 - Aluminum alloys - 144 pages
E22: Aging 10 h at T=160 °C | H22: ? | J22: '
D23: C=896 J/kg-°C MatWeb: Online Materials Information Resource | E23: electrical.thermal efficiency of furnaces=70% "Design and construction of an electric heat treatment furnace using locally sourced materials Anaidhuno UP J111 and Ologe SO , World Journal of Advanced Research and Reviews, 2024, 22(02), 175–184
E24: Painting | F24: same as carbon paint | H24: same as carbon paint | J24: ask professor, no resources…
E25: Transportation
D27: heavy load, truck, no trailer, containers | E27: road | F27: 1.8 | G27: MJ/t/km | H27: 0.1669 | I27: kg CO2 eq./km/t | J27: https://cedelft.eu/wp-content/uploads/sites/2/2021/03/CE_Delft_190325_STREAM_Freight_Transport_2020_FINAL.pdf?utm_source=chatgpt.com
D28: 0-999 TEU, heavy load, containers | E28: ship | F28: 0.36 | G28: MJ/t/km | H28: 0.034 | I28: kg CO2 eq./km/t | J28: https://cedelft.eu/wp-content/uploads/sites/2/2021/03/CE_Delft_190325_STREAM_Freight_Transport_2020_FINAL.pdf?utm_source=chatgpt.com
D29: long, heavy load, electric, containers | E29: rail | F29: 0.08 | G29: MJ/t/km | H29: 0.0108 | I29: kg CO2 eq./km/t | J29: https://cedelft.eu/wp-content/uploads/sites/2/2021/03/CE_Delft_190325_STREAM_Freight_Transport_2020_FINAL.pdf?utm_source=chatgpt.com
D31: Carbon Fiber: | F31: Energy | G31: Unit | H31: CO2 eq. emission | I31: Unit
D33: Fiber production: | E33: Polymerization | F33: 199.54 | G33: MJ/kg | H33: =F33*$H$5 -> 26.882472 | I33: kg CO2 eq./kg | J33: Manufacturing Energy Intensity and Opportunity Analysis for Fiber-Reinforced Polymer Composites
E34: Wet spinning | F34: 194.91 | G34: MJ/kg | H34: =F34*$H$5 -> 26.258708 | I34: kg CO2 eq./kg | J34: Manufacturing Energy Intensity and Opportunity Analysis for Fiber-Reinforced Polymer Composites
E35: Oxidation/ Carbonisation | F35: 316.09 | G35: MJ/kg | H35: =F35*$H$5 -> 42.584347 | I35: kg CO2 eq./kg | J35: Manufacturing Energy Intensity and Opportunity Analysis for Fiber-Reinforced Polymer Composites
E36: Finish/ Surface treatment | F36: 24.99 | G36: MJ/kg | H36: =F36*$H$5 -> 3.3667083 | I36: kg CO2 eq./kg | J36: Manufacturing Energy Intensity and Opportunity Analysis for Fiber-Reinforced Polymer Composites
E37: transportation | F37: =60*F$27/1000+300*F$28/1000 -> 0.216 | G37: MJ/kg | H37: =60*H$27/1000+280*H$28/1000 -> 0.019534 | I37: kg CO2 eq./kg | J37: 60 km road, 280km ship. Masaki - Matsuyama - Osaka - Otsu | K37: http://ports.com/sea-route/port-of-matsuyama,japan/port-of-santos,brazil/#/?a=4669&b=0&c=Port%20of%20Tokyo,%20Japan&d=Port%20of%20Osaka
E38: total per kg: | F38: =F33+F34+F35+F36 -> 735.53 | G38: MJ/kg | H38: =H33+H34+H35+H36 -> 99.092236 | I38: kg CO2 eq./kg
E39: weight | F39: =(F50)*F53 -> 0.6552 | G39: kg
E40: total for one bike: | F40: =F38*$F$39 -> 481.91926 | G40: MJ/bike | H40: =H38*$F$39 -> 64.925233 | I40: kg CO2 eq./ bike
D42: Resin production: | E42: epoxy resin | F42: 74.29 | G42: MJ/kg | H42: =F42*$H$5 -> 10.008514 | I42: kg CO2 eq./kg | J42: Manufacturing Energy Intensity and Opportunity Analysis for Fiber-Reinforced Polymer Composites
E43: total per kg: | F43: =F42 -> 74.29 | G43: MJ/kg | H43: =H42 -> 10.008514 | I43: kg CO2 eq./kg | J43: NEGOITA C
E44: weight | F44: =(1-F50)*F53 -> 0.3528 | G44: kg
E45: total for one bike: | F45: =F43*$F$44 -> 26.209512 | G45: MJ/bike | H45: =H43*$F$44 -> 3.5310037 | I45: kg CO2 eq. / bike
D47: prepreg production: | E47: prepregging | F47: 40.04 | G47: MJ/kg | H47: =F47*$H$5 -> 5.3942778 | I47: kg CO2 eq./kg | J47: Manufacturing Energy Intensity and Opportunity Analysis for Fiber-Reinforced Polymer Composites
...

Sheet CF Recycling
B3: Landfill | C3: 1.11 | D3: MJ/kg | E3: 0.14 | F3: kg CO2/kg
B4: Incineration | C4: 34 | D4: MJ/kg | E4: 3.12 | F4: kg CO2/kg
B5: Incineration recovery | C5: -10.51 | D5: MJ/kg | E5: 1.23 | F5: kg CO2/kg
B6: Mechanical rcl | C6: 2.03 | D6: MJ/kg | E6: =C6*0.07 -> 0.1421 | F6: kg CO2/kg
B7: Pyrolysis rcl | C7: 37.36 | D7: MJ/kg | E7: 5.4 | F7: kg CO2/kg
B8: Fluidized bed rcl | C8: 10.25 | D8: MJ/kg | E8: 1.56 | F8: kg CO2/kg
B9: Solvolysis | C9: 38.39 | D9: MJ/kg | E9: =C9*0.07 -> 2.6873 | F9: kg CO2/kg

Sheet Results
B6: Result Summary:
D7: Energy Consumption [MJ/bike] | E7: Aluminium Frame | F7: Percentages [%] | G7: Carbon Fiber Frame | H7: Percentages [%]
D8: Raw Material Extruction | E8: 408.7382 | F8: =E8/E13*100 -> 50.137826 | G8: =CF!F104 -> 550.94453 | H8: =G8/G13*100 -> 88.48609
D9: Manufacturing | E9: 298.799 | F9: =E9/E13*100 -> 36.652146 | G9: =CF!F105 -> 49.88468 | H9: =G9/G13*100 -> 8.0118779
D10: Use Phase | E10: 0 | F10: =E10/E13*100 -> 0 | G10: 0 | H10: =G10/G13*100 -> 0
D11: EoL | E11: 88.8 | F11: =E11/E13*100 -> 10.892642 | G11: =CF!F106 -> 15.017333 | H11: =G11/G13*100 -> 2.4119036
D12: Transportation | E12: 18.892 | F12: =E12/E13*100 -> 2.3173851 | G12: =CF!F107 -> 6.7875101 | H12: =G12/G13*100 -> 1.0901283
D13: Total | E13: =SUM(E8:E12) -> 815.2292 | F13: =SUM(F8:F12) -> 100 | G13: =SUM(G8:G12) -> 622.63405 | H13: =SUM(H8:H12) -> 100
D15: GWP [kg CO2/bike] | E15: Aluminium Frame | F15: Percentages [%] | G15: Carbon Fiber Frame | H15: Percentages [%]
D16: Raw Material Extruction | E16: 65.398 | F16: =E16/E21*100 -> 51.42282 | G16: 74.29 | H16: =G16/G21*100 -> 87.035796
D17: Manufacturing | E17: 53.781 | F17: =E17/E21*100 -> 42.288307 | G17: =CF!H105 -> 8.4971093 | H17: =G17/G21*100 -> 9.9549424
D18: Use Phase | E18: 0 | F18: =E18/E21*100 -> 0 | G18: 0 | H18: =G18/G21*100 -> 0
D19: EoL | E19: 6.216 | F19: =E19/E21*100 -> 4.8876762 | G19: =CF!H106 -> 1.9278726 | H19: =G19/G21*100 -> 2.2586341
D20: Transportation | E20: 1.782 | F20: =E20/E21*100 -> 1.4011968 | G20: =CF!H107 -> 0.64070326 | H20: =G20/G21*100 -> 0.75062751
D21: Total: | E21: =SUM(E16:E20) -> 127.177 | F21: =SUM(F16:F20) -> 100 | G21: =SUM(G16:G20) -> 85.355685 | H21: =SUM(H16:H20) -> 100
C25: DALY | D25: Characterization factor | E25: 1.13e-08 | F25: DALY/kg CO2
D26: Al | E26: CF
C27: CO2 eq | D27: 127.177 | E27: 85.355685 | F27: kg CO2
C28: DALY | D28: =D27*$E$25 -> 1.4371001e-06 | E28: =E27*$E$25 -> 9.6451924e-07 | F28: DALY
E29: Aluminium | F29: 464.2645
E30: Carbon Fiber | F30: =G13 -> 622.63405
F31: Kg Co2 eq
E32: Aluminium | F32: 102.609
E33: Carbon Fiber | F33: =G21 -> 85.355685

Sheet Shipping Al
A1: Shipping
B2: China--> Taiwan
B19: Taiwan to netherlands
H25: =2.35*'Shipping Al'!J9*G8/1000 -> 0
